[2024-11-15T13:08:24.328+0000] {taskinstance.py:1956} INFO - Dependencies all met for dep_context=non-requeueable deps ti=<TaskInstance: ml_pipeline_dag.preprocess_data manual__2024-11-15T13:08:14.777902+00:00 [queued]>
[2024-11-15T13:08:24.333+0000] {taskinstance.py:1956} INFO - Dependencies all met for dep_context=requeueable deps ti=<TaskInstance: ml_pipeline_dag.preprocess_data manual__2024-11-15T13:08:14.777902+00:00 [queued]>
[2024-11-15T13:08:24.334+0000] {taskinstance.py:2170} INFO - Starting attempt 1 of 2
[2024-11-15T13:08:24.342+0000] {taskinstance.py:2191} INFO - Executing <Task(PythonOperator): preprocess_data> on 2024-11-15 13:08:14.777902+00:00
[2024-11-15T13:08:24.354+0000] {standard_task_runner.py:60} INFO - Started process 340 to run task
[2024-11-15T13:08:24.357+0000] {standard_task_runner.py:87} INFO - Running: ['***', 'tasks', 'run', 'ml_pipeline_dag', 'preprocess_data', 'manual__2024-11-15T13:08:14.777902+00:00', '--job-id', '23', '--raw', '--subdir', 'DAGS_FOLDER/random.py', '--cfg-path', '/tmp/tmpcj_s0eg1']
[2024-11-15T13:08:24.359+0000] {standard_task_runner.py:88} INFO - Job 23: Subtask preprocess_data
[2024-11-15T13:08:24.418+0000] {task_command.py:423} INFO - Running <TaskInstance: ml_pipeline_dag.preprocess_data manual__2024-11-15T13:08:14.777902+00:00 [running]> on host 8b834e0277f8
[2024-11-15T13:08:24.467+0000] {taskinstance.py:2480} INFO - Exporting env vars: AIRFLOW_CTX_DAG_OWNER='suvarna' AIRFLOW_CTX_DAG_ID='ml_pipeline_dag' AIRFLOW_CTX_TASK_ID='preprocess_data' AIRFLOW_CTX_EXECUTION_DATE='2024-11-15T13:08:14.777902+00:00' AIRFLOW_CTX_TRY_NUMBER='1' AIRFLOW_CTX_DAG_RUN_ID='manual__2024-11-15T13:08:14.777902+00:00'
[2024-11-15T13:08:24.468+0000] {taskinstance.py:2698} ERROR - Task failed with exception
Traceback (most recent call last):
  File "/home/airflow/.local/lib/python3.8/site-packages/airflow/models/taskinstance.py", line 433, in _execute_task
    result = execute_callable(context=context, **execute_callable_kwargs)
  File "/home/airflow/.local/lib/python3.8/site-packages/airflow/operators/python.py", line 199, in execute
    return_value = self.execute_callable()
  File "/home/airflow/.local/lib/python3.8/site-packages/airflow/operators/python.py", line 216, in execute_callable
    return self.python_callable(*self.op_args, **self.op_kwargs)
  File "/opt/airflow/dags/random.py", line 29, in preprocess_data
    X = global_df.drop('target', axis=1)
AttributeError: 'NoneType' object has no attribute 'drop'
[2024-11-15T13:08:24.474+0000] {taskinstance.py:1138} INFO - Marking task as UP_FOR_RETRY. dag_id=ml_pipeline_dag, task_id=preprocess_data, execution_date=20241115T130814, start_date=20241115T130824, end_date=20241115T130824
[2024-11-15T13:08:24.481+0000] {standard_task_runner.py:107} ERROR - Failed to execute job 23 for task preprocess_data ('NoneType' object has no attribute 'drop'; 340)
[2024-11-15T13:08:24.496+0000] {local_task_job_runner.py:234} INFO - Task exited with return code 1
[2024-11-15T13:08:24.520+0000] {taskinstance.py:3280} INFO - 0 downstream tasks scheduled from follow-on schedule check
