[2024-11-15T13:08:24.328+0000] {taskinstance.py:1956} INFO - Dependencies all met for dep_context=non-requeueable deps ti=<TaskInstance: ml_pipeline_dag.preprocess_data scheduled__2024-11-14T00:00:00+00:00 [queued]>
[2024-11-15T13:08:24.333+0000] {taskinstance.py:1956} INFO - Dependencies all met for dep_context=requeueable deps ti=<TaskInstance: ml_pipeline_dag.preprocess_data scheduled__2024-11-14T00:00:00+00:00 [queued]>
[2024-11-15T13:08:24.334+0000] {taskinstance.py:2170} INFO - Starting attempt 1 of 2
[2024-11-15T13:08:24.347+0000] {taskinstance.py:2191} INFO - Executing <Task(PythonOperator): preprocess_data> on 2024-11-14 00:00:00+00:00
[2024-11-15T13:08:24.357+0000] {standard_task_runner.py:60} INFO - Started process 341 to run task
[2024-11-15T13:08:24.361+0000] {standard_task_runner.py:87} INFO - Running: ['***', 'tasks', 'run', 'ml_pipeline_dag', 'preprocess_data', 'scheduled__2024-11-14T00:00:00+00:00', '--job-id', '22', '--raw', '--subdir', 'DAGS_FOLDER/random.py', '--cfg-path', '/tmp/tmpf7awq08b']
[2024-11-15T13:08:24.362+0000] {standard_task_runner.py:88} INFO - Job 22: Subtask preprocess_data
[2024-11-15T13:08:24.427+0000] {task_command.py:423} INFO - Running <TaskInstance: ml_pipeline_dag.preprocess_data scheduled__2024-11-14T00:00:00+00:00 [running]> on host 8b834e0277f8
[2024-11-15T13:08:24.473+0000] {taskinstance.py:2480} INFO - Exporting env vars: AIRFLOW_CTX_DAG_OWNER='suvarna' AIRFLOW_CTX_DAG_ID='ml_pipeline_dag' AIRFLOW_CTX_TASK_ID='preprocess_data' AIRFLOW_CTX_EXECUTION_DATE='2024-11-14T00:00:00+00:00' AIRFLOW_CTX_TRY_NUMBER='1' AIRFLOW_CTX_DAG_RUN_ID='scheduled__2024-11-14T00:00:00+00:00'
[2024-11-15T13:08:24.475+0000] {taskinstance.py:2698} ERROR - Task failed with exception
Traceback (most recent call last):
  File "/home/airflow/.local/lib/python3.8/site-packages/airflow/models/taskinstance.py", line 433, in _execute_task
    result = execute_callable(context=context, **execute_callable_kwargs)
  File "/home/airflow/.local/lib/python3.8/site-packages/airflow/operators/python.py", line 199, in execute
    return_value = self.execute_callable()
  File "/home/airflow/.local/lib/python3.8/site-packages/airflow/operators/python.py", line 216, in execute_callable
    return self.python_callable(*self.op_args, **self.op_kwargs)
  File "/opt/airflow/dags/random.py", line 29, in preprocess_data
    X = global_df.drop('target', axis=1)
AttributeError: 'NoneType' object has no attribute 'drop'
[2024-11-15T13:08:24.480+0000] {taskinstance.py:1138} INFO - Marking task as UP_FOR_RETRY. dag_id=ml_pipeline_dag, task_id=preprocess_data, execution_date=20241114T000000, start_date=20241115T130824, end_date=20241115T130824
[2024-11-15T13:08:24.487+0000] {standard_task_runner.py:107} ERROR - Failed to execute job 22 for task preprocess_data ('NoneType' object has no attribute 'drop'; 341)
[2024-11-15T13:08:24.498+0000] {local_task_job_runner.py:234} INFO - Task exited with return code 1
[2024-11-15T13:08:24.523+0000] {taskinstance.py:3280} INFO - 0 downstream tasks scheduled from follow-on schedule check
